test:nek_standalone/lowMach.boundary: [664529c8c02e:21547] Wrote -1, expected 8, errno = 1
test:nek_standalone/lowMach.boundary: Error in launching a new task mpiexec -n 4 /home/multiphysics/cardinal/cardinal-opt -i solid_um.i Executioner/num_steps=1 openmc:Problem/particles=1000 openmc:Problem/inactive_batches=5 openmc:Problem/batches=10 --no-gdb-backtrace
runWorker Exception: Traceback (most recent call last):
  File "/home/multiphysics/cardinal/contrib/moose/python/TestHarness/schedulers/RunParallel.py", line 44, in run
    job.run()
  File "/home/multiphysics/cardinal/contrib/moose/python/TestHarness/schedulers/Job.py", line 227, in run
    self.__tester.run(self.timer, self.options)
  File "/home/multiphysics/cardinal/contrib/moose/python/TestHarness/testers/Tester.py", line 390, in run
    self.runCommand(cmd, cwd, timer, options)
  File "/home/multiphysics/cardinal/contrib/moose/python/TestHarness/testers/Tester.py", line 337, in runCommand
    process = subprocess.Popen(cmd, stdout=f, stderr=e, close_fds=False,
  File "/usr/lib/python3.8/subprocess.py", line 858, in __init__
    self._execute_child(args, executable, preexec_fn, close_fds,
  File "/usr/lib/python3.8/subprocess.py", line 1639, in _execute_child
    self.pid = _posixsubprocess.fork_exec(
OSError: [Errno 12] Cannot allocate memory

During handling of the above exception, another exception occurred:

Traceback (most recent call last):
  File "/home/multiphysics/cardinal/contrib/moose/python/TestHarness/schedulers/Scheduler.py", line 408, in runJob
    self.run(job) # Hand execution over to derived scheduler
  File "/home/multiphysics/cardinal/contrib/moose/python/TestHarness/schedulers/RunParallel.py", line 71, in run
    tester.setStatus(tester.error, 'PYTHON EXCEPTION')
AttributeError: 'RunApp' object has no attribute 'error'

runWorker Exception: Traceback (most recent call last):
  File "/home/multiphysics/cardinal/contrib/moose/python/TestHarness/schedulers/Scheduler.py", line 434, in runJob
    self.queueJobs(jobs, j_lock)
  File "/home/multiphysics/cardinal/contrib/moose/python/TestHarness/schedulers/Scheduler.py", line 256, in queueJobs
    self.run_pool.apply_async(self.runJob, (job, jobs, j_lock))
  File "/usr/lib/python3.8/multiprocessing/pool.py", line 455, in apply_async
    self._check_running()
  File "/usr/lib/python3.8/multiprocessing/pool.py", line 350, in _check_running
    raise ValueError("Pool not running")
ValueError: Pool not running

runWorker Exception: Traceback (most recent call last):
  File "/home/multiphysics/cardinal/contrib/moose/python/TestHarness/schedulers/Scheduler.py", line 434, in runJob
    self.queueJobs(jobs, j_lock)
  File "/home/multiphysics/cardinal/contrib/moose/python/TestHarness/schedulers/Scheduler.py", line 256, in queueJobs
    self.run_pool.apply_async(self.runJob, (job, jobs, j_lock))
  File "/usr/lib/python3.8/multiprocessing/pool.py", line 455, in apply_async
    self._check_running()
  File "/usr/lib/python3.8/multiprocessing/pool.py", line 350, in _check_running
    raise ValueError("Pool not running")
ValueError: Pool not running

runWorker Exception: Traceback (most recent call last):
  File "/home/multiphysics/cardinal/contrib/moose/python/TestHarness/schedulers/Scheduler.py", line 434, in runJob
    self.queueJobs(jobs, j_lock)
  File "/home/multiphysics/cardinal/contrib/moose/python/TestHarness/schedulers/Scheduler.py", line 256, in queueJobs
    self.run_pool.apply_async(self.runJob, (job, jobs, j_lock))
  File "/usr/lib/python3.8/multiprocessing/pool.py", line 455, in apply_async
    self._check_running()
  File "/usr/lib/python3.8/multiprocessing/pool.py", line 350, in _check_running
    raise ValueError("Pool not running")
ValueError: Pool not running

runWorker Exception: Traceback (most recent call last):
  File "/home/multiphysics/cardinal/contrib/moose/python/TestHarness/schedulers/Scheduler.py", line 434, in runJob
    self.queueJobs(jobs, j_lock)
  File "/home/multiphysics/cardinal/contrib/moose/python/TestHarness/schedulers/Scheduler.py", line 256, in queueJobs
    self.run_pool.apply_async(self.runJob, (job, jobs, j_lock))
  File "/usr/lib/python3.8/multiprocessing/pool.py", line 455, in apply_async
    self._check_running()
  File "/usr/lib/python3.8/multiprocessing/pool.py", line 350, in _check_running
    raise ValueError("Pool not running")
ValueError: Pool not running

runWorker Exception: Traceback (most recent call last):
  File "/home/multiphysics/cardinal/contrib/moose/python/TestHarness/schedulers/Scheduler.py", line 434, in runJob
    self.queueJobs(jobs, j_lock)
  File "/home/multiphysics/cardinal/contrib/moose/python/TestHarness/schedulers/Scheduler.py", line 256, in queueJobs
    self.run_pool.apply_async(self.runJob, (job, jobs, j_lock))
  File "/usr/lib/python3.8/multiprocessing/pool.py", line 455, in apply_async
    self._check_running()
  File "/usr/lib/python3.8/multiprocessing/pool.py", line 350, in _check_running
    raise ValueError("Pool not running")
ValueError: Pool not running

runWorker Exception: Traceback (most recent call last):
  File "/home/multiphysics/cardinal/contrib/moose/python/TestHarness/schedulers/Scheduler.py", line 434, in runJob
    self.queueJobs(jobs, j_lock)
  File "/home/multiphysics/cardinal/contrib/moose/python/TestHarness/schedulers/Scheduler.py", line 251, in queueJobs
    self.status_pool.apply_async(self.jobStatus, (job, jobs, j_lock))
  File "/usr/lib/python3.8/multiprocessing/pool.py", line 455, in apply_async
    self._check_running()
  File "/usr/lib/python3.8/multiprocessing/pool.py", line 350, in _check_running
    raise ValueError("Pool not running")
ValueError: Pool not running


test:nek_standalone/lowMach.boundary .................................. [FINISHED,min_cpus=2] FAILED (TIMEOUT)
The command '/bin/sh -c ./run_tests -j8' returned a non-zero code: 1